Time slot   0
ld_routine
        Loaded a process at input/proc/p1s, PID: 1 PRIO: 1
        CPU 1: Dispatched process  1
Time slot   1
        Loaded a process at input/proc/p1s, PID: 2 PRIO: 0
Time slot   2
        Loaded a process at input/proc/p1s, PID: 3 PRIO: 0
        CPU 0: Dispatched process  2
Time slot   3
Time slot   4
        CPU 1: Put process  1 to run queue
        CPU 1: Dispatched process  1
Time slot   5
Time slot   6
        CPU 0: Put process  2 to run queue
        CPU 0: Dispatched process  3
Time slot   7
Time slot   8
        CPU 1: Put process  1 to run queue
        CPU 1: Dispatched process  1
Time slot   9
Time slot  10
        CPU 0: Put process  3 to run queue
        CPU 0: Dispatched process  2
        CPU 1: Processed  1 has finished
        CPU 1: Dispatched process  3
Time slot  11
Time slot  12
Time slot  13
Time slot  14
        CPU 0: Put process  2 to run queue
        CPU 0: Dispatched process  2
        CPU 1: Put process  3 to run queue
        CPU 1: Dispatched process  3
Time slot  15
Time slot  16
        CPU 0: Processed  2 has finished
        CPU 0 stopped
        CPU 1: Processed  3 has finished
        CPU 1 stopped
tronganh@ubuntu:~/os/assignment/ossim_source_code_part2_hk231_paging$ ./os sched
Time slot   0
ld_routine
        Loaded a process at input/proc/p1s, PID: 1 PRIO: 1
Time slot   1
        CPU 1: Dispatched process  1
        Loaded a process at input/proc/p1s, PID: 2 PRIO: 0
Time slot   2
        Loaded a process at input/proc/p1s, PID: 3 PRIO: 0
        CPU 0: Dispatched process  2
Time slot   3
Time slot   4
Time slot   5
        CPU 1: Put process  1 to run queue
        CPU 1: Dispatched process  1
Time slot   6
        CPU 0: Put process  2 to run queue
        CPU 0: Dispatched process  3
Time slot   7
Time slot   8
Time slot   9
        CPU 1: Put process  1 to run queue
        CPU 1: Dispatched process  1
Time slot  10
        CPU 0: Put process  3 to run queue
        CPU 0: Dispatched process  2
Time slot  11
        CPU 1: Processed  1 has finished
        CPU 1: Dispatched process  3
Time slot  12
Time slot  13
Time slot  14
        CPU 0: Put process  2 to run queue
        CPU 0: Dispatched process  2
Time slot  15
        CPU 1: Put process  3 to run queue
        CPU 1: Dispatched process  3
Time slot  16
        CPU 0: Processed  2 has finished
        CPU 0 stopped
Time slot  17
        CPU 1: Processed  3 has finished
        CPU 1 stopped
tronganh@ubuntu:~/os/assignment/ossim_source_code_part2_hk231_paging$ ./os sched
Time slot   0
ld_routine
        Loaded a process at input/proc/p1s, PID: 1 PRIO: 1
        CPU 1: Dispatched process  1
Time slot   1
        Loaded a process at input/proc/p1s, PID: 2 PRIO: 0
        CPU 0: Dispatched process  2
Time slot   2
        Loaded a process at input/proc/p1s, PID: 3 PRIO: 0
Time slot   3
Time slot   4
        CPU 1: Put process  1 to run queue
        CPU 1: Dispatched process  1
Time slot   5
        CPU 0: Put process  2 to run queue
        CPU 0: Dispatched process  3
Time slot   6
Time slot   7
Time slot   8
        CPU 1: Put process  1 to run queue
        CPU 1: Dispatched process  1
Time slot   9
        CPU 0: Put process  3 to run queue
        CPU 0: Dispatched process  2
Time slot  10
        CPU 1: Processed  1 has finished
        CPU 1: Dispatched process  3
Time slot  11
Time slot  12
Time slot  13
        CPU 0: Put process  2 to run queue
        CPU 0: Dispatched process  2
        CPU 1: Put process  3 to run queue
        CPU 1: Dispatched process  3
Time slot  14
Time slot  15
        CPU 0: Processed  2 has finished
        CPU 0 stopped
Time slot  16
        CPU 1: Processed  3 has finished
        CPU 1 stopped